Workbook
Name Display_Week: 'Project schedule'!$W$2
Name Project_Start: 'Project schedule'!$W$1
Name task_end: 'Project schedule'!$L1
Name task_progress: 'Project schedule'!$F1
Name task_start: 'Project schedule'!$K1
Name today: TODAY()

Sheet Project schedule
B1: Liugong Finance | O1: Date: | W1: 46013
B2: IT DEPT | O2: Display week: | W2: 6
O4: =O5 -> 46034 | V4: =V5 -> 46041 | AC4: =AC5 -> 46048 | AJ4: =AJ5 -> 46055 | AQ4: =AQ5 -> 46062 | AX4: =AX5 -> 46069 | BE4: =BE5 -> 46076 | BL4: =BL5 -> 46083
B5: TASK | C5: Department | D5: ASSIGNED TO | E5: Business SOP | F5: PROGRESS | G5: SYSTEM READINESS | H5: LINKED CRs | I5: DELIVERY | J5: STATUS | K5: START | L5: END | O5: =Project_Start-WEEKDAY(Project_Start,1)+2+7*(Display_Week-3) -> 46034 | P5: =O5+1 -> 46035 | Q5: =P5+1 -> 46036 | R5: =Q5+1 -> 46037 | S5: =R5+1 -> 46038 | T5: =S5+1 -> 46039 | U5: =T5+1 -> 46040 | V5: =U5+1 -> 46041 | W5: =V5+1 -> 46042 | ... BR5: =BQ5+1 -> 46089
O6: =LEFT(TEXT(O5,"ddd"),1) -> M | P6: =LEFT(TEXT(P5,"ddd"),1) -> T | Q6: =LEFT(TEXT(Q5,"ddd"),1) -> W | R6: =LEFT(TEXT(R5,"ddd"),1) -> T | S6: =LEFT(TEXT(S5,"ddd"),1) -> F | T6: =LEFT(TEXT(T5,"ddd"),1) -> S | U6: =LEFT(TEXT(U5,"ddd"),1) -> S | V6: =LEFT(TEXT(V5,"ddd"),1) -> M | ... BR6: =LEFT(TEXT(BR5,"ddd"),1) -> S
A7: Do not delete this row. This row is hidden to preserve a formula that is used to highlight the current day within the project schedule. | N7: =IF(OR(ISBLANK(task_start),ISBLANK(task_end)),"",task_end-task_start+1)
B8: Application In | C8: BS | E8: =AVERAGE(E9:E13) -> 0 | F8: =AVERAGE(F9:F13) -> 1 | G8: =AVERAGE(G9:G13) -> 0.96 | K8: =MIN(K9:K13) -> 46013 | L8: =MAX(L9:L13) -> 46080 | N8: =IF(OR(ISBLANK(task_start),ISBLANK(task_end)),"",task_end-task_start+1) -> 68
B9: 1. Select Relevent Products, Dealer Information | D9: Bu Arianti, Pak Olly | E9: 0 | F9: 1 | G9: 0.8 | H9: - | I9: - | K9: =Project_Start -> 46013 | L9: =K9+22 -> 46035 | N9: =IF(OR(ISBLANK(task_start),ISBLANK(task_end)),"",task_end-task_start+1) -> 23
B10: 1. Input Applicant Information 2. Input Address, Reference, Project, shareholder information etc. | D10: Bu Arianti, Pak Olly | E10: 0 | F10: 1 | G10: 1 | H10: LFIUAT001 - Proposoal enhancement | I10: 06th Feb | J10: Pass | K10: =K9 -> 46013 | L10: =K10+39+28 -> 46080 | N10: =IF(OR(ISBLANK(task_start),ISBLANK(task_end)),"",task_end-task_start+1) -> 68
B11: 1. Input Facility Information | D11: Bu Arianti, Pak Olly | E11: 0 | F11: 1 | G11: 1 | K11: =K9 -> 46013 | L11: =K11+22 -> 46035 | N11: =IF(OR(ISBLANK(task_start),ISBLANK(task_end)),"",task_end-task_start+1) -> 23
B12: 1. Submit application For Analysis | D12: Bu Arianti, Pak Olly | E12: 0 | F12: 1 | G12: 1 | H12: Credit Line Management Enhancement | I12: TBD | K12: =K9 -> 46013 | L12: =K12+22 -> 46035 | N12: =IF(OR(ISBLANK(task_start),ISBLANK(task_end)),"",task_end-task_start+1) -> 23
B13: Stationary/Document/Reports | D13: Bu Arianti, Pak Olly | E13: 0 | F13: 1 | G13: 1 | K13: =K9 -> 46013 | L13: =K13+22 -> 46035 | N13: =IF(OR(ISBLANK(task_start),ISBLANK(task_end)),"",task_end-task_start+1) -> 23
B14: CAFA | C14: CA | E14: =AVERAGE(E15:E19) -> 0 | F14: =AVERAGE(F15:F19) -> 1 | G14: =AVERAGE(G15:G19) -> 1 | K14: =MIN(K15:K19) -> 46013 | L14: =MAX(L15:L19) -> 46080 | N14: =IF(OR(ISBLANK(task_start),ISBLANK(task_end)),"",task_end-task_start+1) -> 68
B15: 1. Finacial Analaysis of Facility request | D15: Bu Arianti, Pak Olly, Bu Ria | E15: 0 | F15: 1 | G15: 1 | K15: =Project_Start -> 46013 | L15: =K15+22 -> 46035 | N15: =IF(OR(ISBLANK(task_start),ISBLANK(task_end)),"",task_end-task_start+1) -> 23
B16: 1. AML, CFT Scoring & analysis | C16: AML | D16: Pak Pram | E16: 0 | F16: 1 | G16: 1 | H16: AML Enhancement (Transaction Monitoring) | I16: 06th Feb | J16: Pass | K16: =K15 -> 46013 | L16: =K16+39+28 -> 46080 | N16: =IF(OR(ISBLANK(task_start),ISBLANK(task_end)),"",task_end-task_start+1) -> 68
B17: 1. Change Request process | D17: Bu Arianti, Pak Olly, Bu Ria | E17: 0 | F17: 1 | G17: 1 | K17: =K15 -> 46013 | L17: =K17+22 -> 46035 | N17: =IF(OR(ISBLANK(task_start),ISBLANK(task_end)),"",task_end-task_start+1) -> 23
B18: 1. Dealer Recourse | D18: Bu Arianti, Pak Olly, Bu Ria | E18: 0 | F18: 1 | G18: 1 | K18: =K15 -> 46013 | L18: =K18+22 -> 46035 | N18: =IF(OR(ISBLANK(task_start),ISBLANK(task_end)),"",task_end-task_start+1) -> 23
B19: Staionary/Document | D19: Bu Arianti, Pak Olly, Bu Ria | E19: 0 | F19: 1 | G19: 1 | K19: =K15 -> 46013 | L19: =K19+22 -> 46035 | N19: =IF(OR(ISBLANK(task_start),ISBLANK(task_end)),"",task_end-task_start+1) -> 23
B20: Signing CLF | C20: CA | E20: =AVERAGE(E21:E23) -> 0 | F20: =AVERAGE(F21:F23) -> 1 | G20: =AVERAGE(G21:G23) -> 1 | K20: =MIN(K21:K23) -> 46013 | L20: =MAX(L21:L23) -> 46080 | N20: =IF(OR(ISBLANK(task_start),ISBLANK(task_end)),"",task_end-task_start+1) -> 68
B21: 1. Votting Process initiated 2. Votting process Completed | D21: Bu Arianti, Pak Olly, Bu Ria & Credit Commetti | E21: 0 | F21: 1 | G21: 1 | H21: LFIUAT010 - Modification Voting Approval Screen | I21: 06th Feb | J21: Pass | K21: =Project_Start -> 46013 | L21: =K21+39+28 -> 46080 | N21: =IF(OR(ISBLANK(task_start),ISBLANK(task_end)),"",task_end-task_start+1) -> 68
B22: 1. Facility Approval Request Approval 2. Conditional Approval | D22: Bu Arianti, Pak Olly, Bu Ria & Credit Commetti | E22: 0 | F22: 1 | G22: 1 | H22: LFIUAT011 - Adjusment Voting Screen Details | I22: 06th Feb | J22: Pass | K22: =K21 -> 46013 | L22: =K22+39+28 -> 46080 | N22: =IF(OR(ISBLANK(task_start),ISBLANK(task_end)),"",task_end-task_start+1) -> 68
B23: 5. Document/Stationary check | D23: Bu Arianti, Pak Olly, Bu Ria | E23: 0 | F23: 1 | G23: 1 | K23: =K21 -> 46013 | L23: =K15+22 -> 46035 | N23: =IF(OR(ISBLANK(task_start),ISBLANK(task_end)),"",task_end-task_start+1) -> 23
B24: Document Printing | C24: BS | E24: =AVERAGE(E25:E30) -> 0 | F24: =AVERAGE(F25:F30) -> 1 | G24: =AVERAGE(G25:G30) -> 1 | K24: =MIN(K25:K30) -> 46013 | L24: =MAX(L25:L30) -> 46080 | N24: =IF(OR(ISBLANK(task_start),ISBLANK(task_end)),"",task_end-task_start+1) -> 68
B25: 1. Asset Application creation | D25: Bu Arianti, Pak Olly, | E25: 0 | F25: 1 | G25: 1 | H25: LFIUAT003 - Application of Disbursement Mandatory Field Modification | I25: 06th Feb | J25: Pass | K25: =Project_Start -> 46013 | L25: =K25+22 -> 46035 | N25: =IF(OR(ISBLANK(task_start),ISBLANK(task_end)),"",task_end-task_start+1) -> 23
B26: 1. Check Structure & non- structure plans 2. Check Multi assets in application | D26: Bu Arianti, Pak Olly, | E26: 0 | F26: 1 | G26: 1 | H26: Club Asset | I26: 06th Feb | J26: Pass | K26: =K25 -> 46013 | L26: =K26+39+28 -> 46080 | N26: =IF(OR(ISBLANK(task_start),ISBLANK(task_end)),"",task_end-task_start+1) -> 68
B27: 1. Check Repayment Plan Data 2. Check Insurance, Subsidy | D27: Bu Arianti, Pak Olly, Bu Ria | E27: 0 | F27: 1 | G27: 1 | H27: Structured Type - Principal % LFIUAT006 - Cross Default/Cross Collateral Function | I27: 13th March TBD | J27: In Development | K27: =K25 -> 46013 | L27: =K27+22 -> 46035 | N27: =IF(OR(ISBLANK(task_start),ISBLANK(task_end)),"",task_end-task_start+1) -> 23
B28: 1. Submit asset application For Approval | D28: Bu Arianti, Pak Olly, Bu Ria | E28: 0 | F28: 1 | G28: 1 | K28: =K25 -> 46013 | L28: =K28+22 -> 46035 | N28: =IF(OR(ISBLANK(task_start),ISBLANK(task_end)),"",task_end-task_start+1) -> 23
B29: 1. Convert application into Contract | D29: Bu Arianti, Pak Olly, Bu Ria | E29: 0 | F29: 1 | G29: 1 | H29: Calculation Simulation | I29: 06th Feb | J29: Pass | K29: =K25 -> 46013 | L29: =K29+22 -> 46035 | N29: =IF(OR(ISBLANK(task_start),ISBLANK(task_end)),"",task_end-task_start+1) -> 23
B30: 1. Check Stationary/Documents | D30: Bu Arianti, Pak Olly, Bu Ria | E30: 0 | F30: 1 | G30: 1 | K30: =K26 -> 46013 | L30: =K30+22 -> 46035 | N30: =IF(OR(ISBLANK(task_start),ISBLANK(task_end)),"",task_end-task_start+1) -> 23
B31: Disbursement | C31: BS | E31: =AVERAGE(E32:E40) -> 0 | F31: =AVERAGE(F32:F40) -> 0.88888889 | G31: =AVERAGE(G32:G40) -> 0.94444444 | K31: =MIN(K32:K40) -> 46013 | L31: =MAX(L32:L40) -> 46112 | N31: =IF(OR(ISBLANK(task_start),ISBLANK(task_end)),"",task_end-task_start+1) -> 100
B32: 1. Check Financial data in Contract Actiation | D32: Bu Arianti, Pak Olly, Bu Julia | E32: 0 | F32: 1 | G32: 1 | K32: =Project_Start -> 46013 | L32: =K32+22 -> 46035 | N32: =IF(OR(ISBLANK(task_start),ISBLANK(task_end)),"",task_end-task_start+1) -> 23
B33: 1. Input BAST, PJB data, Ceritifcate of Ownershipt etc… | D33: Bu Arianti, Pak Olly, Bu Julia | E33: 0 | F33: 1 | G33: 1 | H33: LFIUAT004 - Contract Activation Enhancement | I33: 06th Feb | J33: Pass | K33: =K32 -> 46013 | L33: =K33+39+28 -> 46080 | N33: =IF(OR(ISBLANK(task_start),ISBLANK(task_end)),"",task_end-task_start+1) -> 68
B34: 1. Check if Financial Modification is required | D34: Bu Arianti, Pak Olly, Bu Julia | E34: 0 | F34: 1 | G34: 1 | K34: =K32 -> 46013 | L34: =K34+22 -> 46035 | N34: =IF(OR(ISBLANK(task_start),ISBLANK(task_end)),"",task_end-task_start+1) -> 23
B35: 1. PDC Management | C35: Accounting | D35: Bu Arianti, Pak Olly, Pak Richard, Bu Julia | E35: 0 | F35: 0.5 | G35: 1 | H35: LFIUAT007 - PDC Auto Allocate Features | I35: TBD | K35: =K32 -> 46013 | L35: =K35+22 -> 46035 | N35: =IF(OR(ISBLANK(task_start),ISBLANK(task_end)),"",task_end-task_start+1) -> 23
B36: 1. Contract Go Live | D36: Bu Arianti, Pak Olly, Pak Richard, Bu Julia | E36: 0 | F36: 1 | G36: 1 | H36: LFIUAT004 - Contract Activation Enhancement | I36: 06th Feb | J36: Pass | K36: =K32 -> 46013 | L36: =K36+22 -> 46035 | N36: =IF(OR(ISBLANK(task_start),ISBLANK(task_end)),"",task_end-task_start+1) -> 23
B37: 1. Payable Generation | D37: Bu Arianti, Pak Olly, Pak Richard, Bu Julia | E37: 0 | F37: 1 | G37: 1 | K37: =K36 -> 46013 | L37: =K37+39+28 -> 46080 | N37: =IF(OR(ISBLANK(task_start),ISBLANK(task_end)),"",task_end-task_start+1) -> 68
B38: 1. Disbursement to Dealer | C38: Accounting | D38: Pak Richard | E38: 0 | F38: 1 | G38: 1 | K38: =K37 -> 46013 | L38: =K38+39+28 -> 46080 | N38: =IF(OR(ISBLANK(task_start),ISBLANK(task_end)),"",task_end-task_start+1) -> 68
B39: 1. Accounting Generation | C39: Accounting | D39: Bu Julia | E39: 0 | F39: 0.6 | G39: 0.6 | H39: Journel | I39: 13th March | J39: In Development | K39: =L38 -> 46080 | L39: =K39+32 -> 46112 | N39: =IF(OR(ISBLANK(task_start),ISBLANK(task_end)),"",task_end-task_start+1) -> 33
B40: Staionary/Document | D40: Bu Arianti, Pak Olly, Bu Julia | E40: 0 | F40: 0.9 | G40: 0.9 | H40: LFI014 - Stationary Check | I40: 13th March | J40: In Development | K40: =L38 -> 46080 | L40: =K40+32 -> 46112 | N40: =IF(OR(ISBLANK(task_start),ISBLANK(task_end)),"",task_end-task_start+1) -> 33
B41: Collection Process | C41: QA | E41: =AVERAGE(E42:E45) -> 0 | F41: =AVERAGE(F42:F45) -> 0.75 | G41: =AVERAGE(G42:G45) -> 0.875 | K41: =MIN(K42:K45) -> 46013 | L41: =MAX(L42:L45) -> 46142 | N41: =IF(OR(ISBLANK(task_start),ISBLANK(task_end)),"",task_end-task_start+1) -> 130
...

Sheet Overall planning
B2: Phase | C2: System Process flow | D2: Start time | E2: End time | F2: Current Business SOP | G2: Core System Readiness (NETSOL) | H2: Production Business Case Exists | I2: Status | J2: Automation Target % | K2: Automation Achievement % | L2: UAT(new)&requirements | P2: Process reengineering | S2: Comment
L3: 1.Using real-case testing, gathering feedback on issues, and proposing actual needs 2.Stationary/Document/Reports | M3: System debugging | N3: Retest and go live | P3: 1.Process improvement 2.Online transformation of offline processes 3.Disassembly process flow nodes and PIC 4.New Reports | Q3: System debugging | R3: Retest and go live
B5: From application in to payment receive | C5: Application In | D5: ='Project schedule'!K8 -> 46013 | E5: ='Project schedule'!L8 -> 46080 | F5: 1 | G5: ='Project schedule'!G8 -> 0.96 | H5: Yes | I5: =#REF! -> #REF! | J5: 0.9 | K5: 0.7 | L5: 1 | M5: 0.9 | N5: 0 | P5: 0.75 | Q5: 0 | R5: 0 | S5: OCR
C6: CAFA | D6: ='Project schedule'!K14 -> 46013 | E6: ='Project schedule'!L14 -> 46080 | F6: 1 | G6: ='Project schedule'!G14 -> 1 | H6: Yes | I6: =#REF! -> #REF! | J6: 0.7 | K6: 0.5 | L6: 1 | M6: 1 | N6: 0 | P6: 0.7 | Q6: 0 | R6: 0 | S6: Onsite check, Manual Review, Decision Engine
C7: Signing CLF | D7: ='Project schedule'!K20 -> 46013 | E7: ='Project schedule'!L20 -> 46080 | F7: 1 | G7: ='Project schedule'!G20 -> 1 | H7: Yes | I7: =#REF! -> #REF! | J7: 0.8 | K7: 0.6 | L7: 1 | M7: 1 | N7: 0 | P7: 0.8 | Q7: 0 | R7: 0 | S7: e-Sign
C8: Document Printing | D8: ='Project schedule'!K24 -> 46013 | E8: ='Project schedule'!L24 -> 46080 | F8: 1 | G8: ='Project schedule'!G24 -> 1 | H8: Yes | I8: =#REF! -> #REF! | J8: 0.95 | K8: 0.9 | L8: 1 | M8: 0.95 | N8: 0 | P8: 0.6 | Q8: 0 | R8: 0
C9: Disbursement | D9: ='Project schedule'!K31 -> 46013 | E9: ='Project schedule'!L31 -> 46112 | F9: 1 | G9: ='Project schedule'!G31 -> 0.94444444 | H9: Yes | I9: =#REF! -> #REF! | J9: 0.9 | K9: 0.7 | L9: 1 | M9: 0.69 | N9: 0 | P9: 0.7 | Q9: 0 | R9: 0 | S9: Bank integration
C10: Collection Process-payment receive | D10: ='Project schedule'!K41 -> 46013 | E10: =E9 -> 46112 | F10: 1 | G10: ='Project schedule'!G41 -> 0.875 | H10: Yes | I10: =#REF! -> #REF! | J10: 0.8 | K10: 0.6 | L10: 0.5 | M10: 0.5 | N10: 0 | P10: 0.1 | Q10: 0 | R10: 0 | S10: Manual follow-up, Notification
C11: Accounting Generation | D11: 46048 | E11: =E10 -> 46112 | F11: 1 | G11: ='Project schedule'!G39 -> 0.6 | H11: Yes | I11: =G11 -> 0.6 | J11: 0.95 | K11: 0.6 | L11: 0.3 | M11: 0.3 | N11: 0 | P11: 0.3 | Q11: 0 | R11: 0
B12: AI | C12: AI | D12: 46054 | E12: 46173 | F12: N/A | I12: 0 | K12: 0 | L12: 0 | M12: 0 | N12: 0 | P12: 0 | Q12: 0 | R12: 0 | S12: Define MVP
B14: QA and others Post-loan management | C14: Payment Default Settlement | D14: ='Project schedule'!K48 -> 46118 | E14: ='Project schedule'!L48 -> 46142 | F14: 1 | G14: ='Project schedule'!G46 -> 0.9 | H14: No | I14: =#REF! -> #REF! | J14: 0.6 | K14: 0.3 | L14: 0 | M14: 0 | N14: 0 | P14: 0 | Q14: 0 | R14: 0 | S14: Legal and customer negotiation
C15: Restrcuturing Process | D15: ='Project schedule'!K54 -> 46118 | E15: ='Project schedule'!L54 -> 46142 | F15: 1 | G15: ='Project schedule'!G52 -> 0.75 | H15: No | I15: =#REF! -> #REF! | J15: 0.5 | K15: 0.3 | L15: 0 | M15: 0 | N15: 0 | P15: 0 | Q15: 0 | R15: 0 | S15: Manual process case by case
C16: Reposession | D16: ='Project schedule'!K59 -> 46118 | E16: ='Project schedule'!L59 -> 46142 | F16: 1 | G16: ='Project schedule'!G57 -> 1 | H16: No | I16: =#REF! -> #REF! | J16: 0.4 | K16: 0.2 | L16: 0 | M16: 0 | N16: 0 | P16: 0 | Q16: 0 | R16: 0 | S16: On-site execution
C17: Inventory Asset Selling | D17: ='Project schedule'!K65 -> 46118 | E17: ='Project schedule'!L65 -> 46142 | F17: 1 | G17: ='Project schedule'!G63 -> 1 | H17: No | I17: =#REF! -> #REF! | J17: 0.6 | K17: 0.4 | L17: 0 | M17: 0 | N17: 0 | P17: 0 | Q17: 0 | R17: 0 | S17: Manual process case by case
C18: Recourse | D18: ='Project schedule'!K72 -> 46142 | E18: ='Project schedule'!L72 -> 46171 | F18: 1 | G18: ='Project schedule'!G70 -> 0.875 | H18: No | I18: =#REF! -> #REF! | J18: 0.5 | K18: 0.3 | L18: 0 | M18: 0 | N18: 0 | P18: 0 | Q18: 0 | R18: 0 | S18: Manual and legal process case by case
C19: BG | D19: ='Project schedule'!K77 -> 46118 | E19: ='Project schedule'!L77 -> 46142 | F19: 1 | G19: ='Project schedule'!G75 -> 0.875 | H19: Yes | I19: =#REF! -> #REF! | J19: 0.7 | K19: 0.6 | L19: 0 | M19: 0 | N19: 0 | P19: 0 | Q19: 0 | R19: 0 | S19: Manual process
C20: Stop Engine | D20: ='Project schedule'!K82 -> 46118 | E20: ='Project schedule'!L80 -> 46142 | F20: 1 | G20: ='Project schedule'!G80 -> 1 | H20: No | I20: =#REF! -> #REF! | J20: 0.8 | K20: 0.4 | L20: 0 | M20: 0 | N20: 0 | P20: 0 | Q20: 0 | R20: 0 | S20: GPS Integration
C21: Block Supply | D21: ='Project schedule'!K88 -> 46118 | E21: ='Project schedule'!L86 -> 46142 | F21: 1 | G21: ='Project schedule'!G86 -> 1 | H21: No | I21: =#REF! -> #REF! | J21: 0.8 | K21: 0.3 | L21: 0 | M21: 0 | N21: 0 | P21: 0 | Q21: 0 | R21: 0 | S21: GPS Integration
C22: Filling Document | D22: ='Project schedule'!K95 -> 46118 | E22: ='Project schedule'!L93 -> 46142 | F22: 1 | G22: ='Project schedule'!G93 -> 0.5 | H22: N/A | I22: =#REF! -> #REF! | J22: 0.9 | K22: 0.5 | L22: 0 | M22: 0 | N22: 0 | P22: 0 | Q22: 0 | R22: 0
C23: Ownership Document Releasing | D23: ='Project schedule'!K101 -> 46118 | E23: ='Project schedule'!L101 -> 46142 | F23: 1 | G23: ='Project schedule'!G99 -> 0.83333333 | H23: No | I23: =#REF! -> #REF! | J23: 0.7 | K23: 0.4 | L23: 0 | M23: 0 | N23: 0 | P23: 0 | Q23: 0 | R23: 0 | S23: Manual process case by case
C24: Complaint Handling | D24: ='Project schedule'!K105 -> 46118 | E24: ='Project schedule'!L105 -> 46142 | F24: 1 | G24: ='Project schedule'!G103 -> 0.83333333 | H24: No | I24: =#REF! -> #REF! | J24: 0.6 | K24: 0.3 | L24: 0 | M24: 0 | N24: 0 | P24: 0 | Q24: 0 | R24: 0 | S24: Manual process case by case
C25: Emoticons | D25: ='Project schedule'!K109 -> 46142 | E25: ='Project schedule'!L109 -> 46171 | F25: 1 | G25: ='Project schedule'!G109 -> 0.5 | H25: Yes | I25: =#REF! -> #REF! | J25: 0.85 | K25: 0.3 | L25: 0 | M25: 0 | N25: 0 | P25: 0 | Q25: 0 | R25: 0 | S25: Parameter List
C26: Risk Control | D26: ='Project schedule'!K118 -> 46136 | E26: ='Project schedule'!L118 -> 46170 | F26: 1 | G26: ='Project schedule'!G116 -> 0.8 | H26: Yes | I26: =#REF! -> #REF! | J26: 0.65 | K26: 0.2 | L26: 0.5 | M26: 0.17 | N26: 0 | P26: 0 | Q26: 0 | R26: 0 | S26: Manual Review
C27: Accounting Generation | D27: ='Project schedule'!K119 -> 46013 | E27: ='Project schedule'!L56 -> 46171 | F27: 1 | G27: ='Project schedule'!G56 -> 0.5 | H27: Yes | I27: =#REF! -> #REF! | J27: 0.95 | K27: 0.6 | L27: 0 | M27: 0 | N27: 0 | P27: 0 | Q27: 0 | R27: 0
C28: ='Project schedule'!B121 -> Decision Engine | D28: ='Project schedule'!K121 -> 46188 | E28: ='Project schedule'!L121 -> 46203 | F28: N/A | G28: ='Project schedule'!F121 -> 0.1 | H28: Yes | I28: 0.1 | J28: 0.95 | K28: =G28 -> 0.1 | L28: 0.1 | M28: 0 | N28: 0 | P28: 0 | Q28: 0 | R28: 0 | S28: Decision Engine
B31: Phase | C31: System Process flow | D31: start time | E31: End time | I31: Status | L31: Process reengineering | P31: UAT(new)&requirements
L32: 1.Process design 2.requirements 3.Disassembly process flow nodes and PIC | M32: System debugging | N32: Retest and go live | P32: 1.Using real-case testing, gathering feedback on issues, and proposing actual needs 2.Stationary/Document/Reports | Q32: System debugging | R32: Retest and go live
B34: System iteration upgrade and new feature development | C34: Iteration - Payment Interface Bank-Enterprise Direct Link | I34: =#REF! -> #REF! | L34: 0 | M34: 0 | N34: 0 | P34: 0 | Q34: 0 | R34: 0 | U34: 项目-核心系统迭代-支付接口银企直联
C35: Iteration - OCR Interface | I35: =#REF! -> #REF! | L35: 0 | M35: 0 | N35: 0 | P35: 0 | Q35: 0 | R35: 0 | U35: 项目-核心系统迭代-OCR接口
C36: Iteration - Notification Interface | I36: =#REF! -> #REF! | L36: 0 | M36: 0 | N36: 0 | P36: 0 | Q36: 0 | R36: 0 | U36: 项目-核心系统迭代-通知接口
C37: Iteration - GPS Interface | I37: =#REF! -> #REF! | L37: 0 | M37: 0 | N37: 0 | P37: 0 | Q37: 0 | R37: 0 | U37: 项目-核心系统迭代-GPS接口
C38: Iteration - Data Warehouse Construction | I38: =#REF! -> #REF! | L38: 0 | M38: 0 | N38: 0 | P38: 0 | Q38: 0 | R38: 0 | U38: 项目-核心系统迭代-数仓搭建（基础框架搭建、数据存储追踪） | V38: (Basic Framework Construction, Data Storage Tracking)
C39: Iteration - SLIK & SILARAS Submission | I39: =#REF! -> #REF! | L39: 0 | M39: 0 | N39: 0 | P39: 0 | Q39: 0 | R39: 0 | U39: 项目-核心系统迭代-SLIK&SILARAS报送
C40: Iteration - Manufacturer AR Management | I40: =#REF! -> #REF! | L40: 0 | M40: 0 | N40: 0 | P40: 0 | Q40: 0 | R40: 0 | U40: 项目-核心系统迭代-厂家AR管理模块（含经销商、厂家界面优化） | V40: (Including Dealer and Manufacturer Interface Optimization)
C41: Iteration - Joint Leasing Module | I41: =#REF! -> #REF! | L41: 0 | M41: 0 | N41: 0 | P41: 0 | Q41: 0 | R41: 0 | U41: 项目-核心系统迭代-联合租赁模块
C42: Iteration - Channel Business Module | I42: =#REF! -> #REF! | L42: 0 | M42: 0 | N42: 0 | P42: 0 | Q42: 0 | R42: 0 | U42: 项目-核心系统迭代-通道业务模块
